Workbook

Sheet Lisez-moi
A7: Analyse des données d'un mémoire (TFE) – Version Excel
A8: Fréquence et facteurs associés à la prééclampsie chez les femmes enceintes – structure hospitalière de Kara, Togo (étude transversale analytique, données simulées)
A10: Avertissement : toutes les données sont entièrement synthétiques (fictives), créées pour l'enseignement. Aucun résultat ne doit être cité comme une donnée réelle.
A12: Ce classeur reprend l'analyse complète du script R « 02_analyse_TFE.R »
A13: • Fonctionne dans Microsoft Excel 2016 et versions ultérieures. Aucune macro, aucun complément : uniquement des formules classiques (COUNTIFS, AVERAGEIFS, SUMPRODUCT, MEDIAN, QUARTILE, CHITEST, HYPGEOMDIST, BETADIST…).
A14: • Tous les résultats sont des formules : si vous modifiez une valeur dans la feuille Donnees, les tableaux, tests et graphiques se recalculent automatiquement (calcul automatique activé).
A15: • Une cellule vide dans Donnees = valeur manquante (NA dans R). Ne tapez pas « NA » ni « 0 » à la place d'une valeur manquante.
A16: • Ne modifiez pas les cellules des feuilles d'analyse : elles contiennent les formules. Les cellules de la feuille Donnees (colonnes A à V) sont les seules à saisir.
A17: • Les colonnes W à AB de la feuille Donnees sont calculées par formule (tranches d'âge, groupes de parité, etc.), comme les fonctions cut() dans R.
A18: • Tests exacts de Fisher : 2 × 2 (Q6, Q7, Q9) calculés pour toutes données ; tableaux 4 × 2 (Q5) et 3 × 2 (Q8) calculés par énumération (feuilles Fisher_Q5 et Fisher_Q8), valables pour les effectifs actuels : un message d'alerte s'affiche si les marges changent.
A20: Correspondance avec le script R et la fiche des 10 questions
A21: Feuille | B21: Contenu | C21: Questions / sections R
A22: Donnees | B22: 400 femmes, 22 variables + 6 colonnes calculées | C22: Section 1 (importation)
A23: Dictionnaire | B23: Signification, type, codage et manquants | C23: Dictionnaire des variables
A24: 1_Exploration | B24: Dimensions, manquants, résumé, aperçu | C24: Section 2 (dim, str, summary, head)
A25: 2_Description | B25: Âge, caractéristiques sociodémographiques et obstétricales ; histogramme | C25: Questions 1 à 3 ; Tableaux 1 et 2
A26: 3_Frequence | B26: Proportion de prééclampsie et types de diagnostic | C26: Question 4 ; Tableau 3
A27: 4_Facteurs | B27: Tableaux croisés, effectifs attendus, choix du test, p-values | C27: Questions 5 à 9 ; Tableau 4
A28: Fisher_2x2, Fisher_Q5, Fisher_Q8 | B28: Calcul du test exact de Fisher | C28: fisher.test()
A29: 5_Comparaison | B29: Test t de Welch, test de Wilcoxon, données du boxplot | C29: Question 10
A30: 6_Tableaux | B30: Tableaux 1 à 5 prêts pour le mémoire (liés aux feuilles d'analyse) | C30: Section 4
A31: 7_Graphiques | B31: 5 graphiques | C31: Section 6 (ggplot2)
A32: 8_Synthese | B32: Synthèse des tests et des résultats | C32: Section 5 et fichier de synthèse
A34: Démarche à retenir
A35: Je formule une question → j'identifie mes variables → je choisis une analyse → j'obtiens un résultat → je l'interprète → je le présente dans mon mémoire.
A36: Attention : facteur associé ne signifie pas cause. Un résultat non significatif (p ≥ 0,05) ne prouve pas l'absence d'association.

Sheet Donnees
A1: id_patiente | B1: age_ans | C1: situation_matrimoniale | D1: niveau_instruction | E1: profession | F1: milieu_residence | G1: gestite | H1: parite | I1: atcd_preeclampsie | J1: atcd_hta_chronique | K1: atcd_familial_hta | L1: atcd_diabete | M1: age_gestationnel_sa | N1: nb_cpn | O1: type_grossesse | P1: imc | Q1: pas_mmhg | R1: pad_mmhg | S1: proteinurie | T1: signes_gravite | U1: type_diagnostic | V1: preeclampsie | W1: tranche_age | X1: groupe_parite | Y1: groupe_cpn | Z1: groupe_age_gest | AA1: rang_age | AB1: inclus_Q6 | AD1: Colonnes W à AB (en bleu-vert) : variables créées par formule (équivalent des cut() de R). Cellule vide = valeur manquante (NA).
A2: F001 | B2: 24 | C2: Mariée | D2: Secondaire | E2: Ménagère | F2: Urbain | G2: 3 | H2: 2 | I2: Non | J2: Non | K2: Non | L2: Non | M2: 36 | N2: 5 | O2: Unique | P2: 19.8 | Q2: 119 | R2: 71 | S2: Négative | T2: Non applicable | U2: Normotendue | V2: Non | W2: =IF(B2="","",IF(B2<=19,"Moins de 20 ans",IF(B2<=29,"20-29 ans",IF(B2<=34,"30-34 ans","35 ans et plus")))) -> 20-29 ans | X2: =IF(H2="","",IF(H2=0,"Nullipare (0)",IF(H2<=2,"1-2 accouchements","3 accouchements et plus"))) -> 1-2 accouchements | Y2: =IF(N2="","",IF(N2<=3,"Moins de 4 CPN",IF(N2<=7,"4 à 7 CPN","8 CPN et plus"))) -> 4 à 7 CPN | Z2: =IF(M2="","",IF(M2<=27,"20-27 SA",IF(M2<=36,"28-36 SA","37 SA et plus"))) -> 28-36 SA | AA2: =RANK(B2,$B$2:$B$401,1)+(COUNTIF($B$2:$B$401,B2)-1)/2 -> 139.5 | AB2: =IF(AND(H2>=1,OR(I2="Oui",I2="Non")),1,0) -> 1
A3: F002 | B3: 24 | C3: Union libre | D3: Secondaire | E3: Élève/Étudiante | F3: Urbain | G3: 2 | H3: 1 | I3: Non | J3: Non | K3: Oui | L3: Non | M3: 40 | N3: 4 | O3: Unique | P3: 21.7 | Q3: 113 | R3: 77 | S3: Négative | T3: Non applicable | U3: Normotendue | V3: Non | W3: =IF(B3="","",IF(B3<=19,"Moins de 20 ans",IF(B3<=29,"20-29 ans",IF(B3<=34,"30-34 ans","35 ans et plus")))) -> 20-29 ans | X3: =IF(H3="","",IF(H3=0,"Nullipare (0)",IF(H3<=2,"1-2 accouchements","3 accouchements et plus"))) -> 1-2 accouchements | Y3: =IF(N3="","",IF(N3<=3,"Moins de 4 CPN",IF(N3<=7,"4 à 7 CPN","8 CPN et plus"))) -> 4 à 7 CPN | Z3: =IF(M3="","",IF(M3<=27,"20-27 SA",IF(M3<=36,"28-36 SA","37 SA et plus"))) -> 37 SA et plus | AA3: =RANK(B3,$B$2:$B$401,1)+(COUNTIF($B$2:$B$401,B3)-1)/2 -> 139.5 | AB3: =IF(AND(H3>=1,OR(I3="Oui",I3="Non")),1,0) -> 1
A4: F003 | B4: 34 | C4: Union libre | D4: Primaire | E4: Ménagère | F4: Rural | G4: 1 | H4: 0 | I4: Non applicable | J4: Non | K4: Non | L4: Non | M4: 33 | N4: 6 | O4: Unique | P4: 29.2 | Q4: 114 | R4: 69 | S4: Négative | T4: Non applicable | U4: Normotendue | V4: Non | W4: =IF(B4="","",IF(B4<=19,"Moins de 20 ans",IF(B4<=29,"20-29 ans",IF(B4<=34,"30-34 ans","35 ans et plus")))) -> 30-34 ans | X4: =IF(H4="","",IF(H4=0,"Nullipare (0)",IF(H4<=2,"1-2 accouchements","3 accouchements et plus"))) -> Nullipare (0) | Y4: =IF(N4="","",IF(N4<=3,"Moins de 4 CPN",IF(N4<=7,"4 à 7 CPN","8 CPN et plus"))) -> 4 à 7 CPN | Z4: =IF(M4="","",IF(M4<=27,"20-27 SA",IF(M4<=36,"28-36 SA","37 SA et plus"))) -> 28-36 SA | AA4: =RANK(B4,$B$2:$B$401,1)+(COUNTIF($B$2:$B$401,B4)-1)/2 -> 372 | AB4: =IF(AND(H4>=1,OR(I4="Oui",I4="Non")),1,0) -> 0
A5: F004 | B5: 20 | C5: Mariée | D5: Secondaire | E5: Commerçante | F5: Rural | G5: 1 | H5: 0 | I5: Non applicable | J5: Non | K5: Non | L5: Non | M5: 34 | N5: 0 | O5: Unique | P5: 21 | Q5: 115 | R5: 70 | S5: Négative | T5: Non applicable | U5: Normotendue | V5: Non | W5: =IF(B5="","",IF(B5<=19,"Moins de 20 ans",IF(B5<=29,"20-29 ans",IF(B5<=34,"30-34 ans","35 ans et plus")))) -> 20-29 ans | X5: =IF(H5="","",IF(H5=0,"Nullipare (0)",IF(H5<=2,"1-2 accouchements","3 accouchements et plus"))) -> Nullipare (0) | Y5: =IF(N5="","",IF(N5<=3,"Moins de 4 CPN",IF(N5<=7,"4 à 7 CPN","8 CPN et plus"))) -> Moins de 4 CPN | Z5: =IF(M5="","",IF(M5<=27,"20-27 SA",IF(M5<=36,"28-36 SA","37 SA et plus"))) -> 28-36 SA | AA5: =RANK(B5,$B$2:$B$401,1)+(COUNTIF($B$2:$B$401,B5)-1)/2 -> 30.5 | AB5: =IF(AND(H5>=1,OR(I5="Oui",I5="Non")),1,0) -> 0
A6: F005 | B6: 20 | C6: Célibataire | D6: Secondaire | E6: Salariée | F6: Urbain | G6: 1 | H6: 0 | I6: Non applicable | J6: Non | K6: Non | L6: Non | M6: 33 | N6: 4 | O6: Unique | P6: 24.1 | Q6: 102 | R6: 66 | S6: Négative | T6: Non applicable | U6: Normotendue | V6: Non | W6: =IF(B6="","",IF(B6<=19,"Moins de 20 ans",IF(B6<=29,"20-29 ans",IF(B6<=34,"30-34 ans","35 ans et plus")))) -> 20-29 ans | X6: =IF(H6="","",IF(H6=0,"Nullipare (0)",IF(H6<=2,"1-2 accouchements","3 accouchements et plus"))) -> Nullipare (0) | Y6: =IF(N6="","",IF(N6<=3,"Moins de 4 CPN",IF(N6<=7,"4 à 7 CPN","8 CPN et plus"))) -> 4 à 7 CPN | Z6: =IF(M6="","",IF(M6<=27,"20-27 SA",IF(M6<=36,"28-36 SA","37 SA et plus"))) -> 28-36 SA | AA6: =RANK(B6,$B$2:$B$401,1)+(COUNTIF($B$2:$B$401,B6)-1)/2 -> 30.5 | AB6: =IF(AND(H6>=1,OR(I6="Oui",I6="Non")),1,0) -> 0
A7: F006 | B7: 24 | C7: Mariée | D7: Secondaire | E7: Agricultrice | F7: Rural | G7: 1 | H7: 0 | I7: Non applicable | J7: Non | K7: Non | L7: Non | M7: 35 | O7: Unique | P7: 30.5 | Q7: 102 | R7: 63 | S7: Négative | T7: Non applicable | U7: Normotendue | V7: Non | W7: =IF(B7="","",IF(B7<=19,"Moins de 20 ans",IF(B7<=29,"20-29 ans",IF(B7<=34,"30-34 ans","35 ans et plus")))) -> 20-29 ans | X7: =IF(H7="","",IF(H7=0,"Nullipare (0)",IF(H7<=2,"1-2 accouchements","3 accouchements et plus"))) -> Nullipare (0) | Y7: =IF(N7="","",IF(N7<=3,"Moins de 4 CPN",IF(N7<=7,"4 à 7 CPN","8 CPN et plus"))) | Z7: =IF(M7="","",IF(M7<=27,"20-27 SA",IF(M7<=36,"28-36 SA","37 SA et plus"))) -> 28-36 SA | AA7: =RANK(B7,$B$2:$B$401,1)+(COUNTIF($B$2:$B$401,B7)-1)/2 -> 139.5 | AB7: =IF(AND(H7>=1,OR(I7="Oui",I7="Non")),1,0) -> 0
A8: F007 | B8: 33 | C8: Mariée | D8: Primaire | E8: Commerçante | F8: Urbain | G8: 3 | H8: 2 | I8: Oui | J8: Non | K8: Oui | L8: Non | M8: 34 | N8: 1 | O8: Unique | P8: 28.9 | Q8: 118 | R8: 67 | S8: Négative | T8: Non applicable | U8: Normotendue | V8: Non | W8: =IF(B8="","",IF(B8<=19,"Moins de 20 ans",IF(B8<=29,"20-29 ans",IF(B8<=34,"30-34 ans","35 ans et plus")))) -> 30-34 ans | X8: =IF(H8="","",IF(H8=0,"Nullipare (0)",IF(H8<=2,"1-2 accouchements","3 accouchements et plus"))) -> 1-2 accouchements | Y8: =IF(N8="","",IF(N8<=3,"Moins de 4 CPN",IF(N8<=7,"4 à 7 CPN","8 CPN et plus"))) -> Moins de 4 CPN | Z8: =IF(M8="","",IF(M8<=27,"20-27 SA",IF(M8<=36,"28-36 SA","37 SA et plus"))) -> 28-36 SA | AA8: =RANK(B8,$B$2:$B$401,1)+(COUNTIF($B$2:$B$401,B8)-1)/2 -> 361.5 | AB8: =IF(AND(H8>=1,OR(I8="Oui",I8="Non")),1,0) -> 1
A9: F008 | B9: 23 | C9: Mariée | D9: Secondaire | E9: Salariée | F9: Rural | G9: 4 | H9: 3 | I9: Non | J9: Non | K9: Oui | L9: Non | M9: 35 | N9: 3 | O9: Unique | P9: 20.5 | Q9: 125 | R9: 84 | S9: Négative | T9: Non applicable | U9: Normotendue | V9: Non | W9: =IF(B9="","",IF(B9<=19,"Moins de 20 ans",IF(B9<=29,"20-29 ans",IF(B9<=34,"30-34 ans","35 ans et plus")))) -> 20-29 ans | X9: =IF(H9="","",IF(H9=0,"Nullipare (0)",IF(H9<=2,"1-2 accouchements","3 accouchements et plus"))) -> 3 accouchements et plus | Y9: =IF(N9="","",IF(N9<=3,"Moins de 4 CPN",IF(N9<=7,"4 à 7 CPN","8 CPN et plus"))) -> Moins de 4 CPN | Z9: =IF(M9="","",IF(M9<=27,"20-27 SA",IF(M9<=36,"28-36 SA","37 SA et plus"))) -> 28-36 SA | AA9: =RANK(B9,$B$2:$B$401,1)+(COUNTIF($B$2:$B$401,B9)-1)/2 -> 103.5 | AB9: =IF(AND(H9>=1,OR(I9="Oui",I9="Non")),1,0) -> 1
A10: F009 | B10: 26 | C10: Célibataire | D10: Primaire | E10: Ménagère | F10: Urbain | G10: 3 | H10: 2 | I10: Oui | J10: Non | K10: Non | L10: Non | M10: 29 | O10: Unique | P10: 32.9 | Q10: 116 | R10: 66 | S10: Négative | T10: Non applicable | U10: Normotendue | V10: Non | W10: =IF(B10="","",IF(B10<=19,"Moins de 20 ans",IF(B10<=29,"20-29 ans",IF(B10<=34,"30-34 ans","35 ans et plus")))) -> 20-29 ans | X10: =IF(H10="","",IF(H10=0,"Nullipare (0)",IF(H10<=2,"1-2 accouchements","3 accouchements et plus"))) -> 1-2 accouchements | Y10: =IF(N10="","",IF(N10<=3,"Moins de 4 CPN",IF(N10<=7,"4 à 7 CPN","8 CPN et plus"))) | Z10: =IF(M10="","",IF(M10<=27,"20-27 SA",IF(M10<=36,"28-36 SA","37 SA et plus"))) -> 28-36 SA | AA10: =RANK(B10,$B$2:$B$401,1)+(COUNTIF($B$2:$B$401,B10)-1)/2 -> 206 | AB10: =IF(AND(H10>=1,OR(I10="Oui",I10="Non")),1,0) -> 1
A11: F010 | B11: 29 | C11: Union libre | D11: Primaire | E11: Ménagère | F11: Urbain | G11: 1 | H11: 0 | I11: Non applicable | J11: Oui | K11: Non | L11: Non | M11: 38 | N11: 2 | O11: Unique | P11: 30.9 | Q11: 149 | R11: 97 | S11: Traces | T11: Oui | U11: Prééclampsie surajoutée | V11: Oui | W11: =IF(B11="","",IF(B11<=19,"Moins de 20 ans",IF(B11<=29,"20-29 ans",IF(B11<=34,"30-34 ans","35 ans et plus")))) -> 20-29 ans | X11: =IF(H11="","",IF(H11=0,"Nullipare (0)",IF(H11<=2,"1-2 accouchements","3 accouchements et plus"))) -> Nullipare (0) | Y11: =IF(N11="","",IF(N11<=3,"Moins de 4 CPN",IF(N11<=7,"4 à 7 CPN","8 CPN et plus"))) -> Moins de 4 CPN | Z11: =IF(M11="","",IF(M11<=27,"20-27 SA",IF(M11<=36,"28-36 SA","37 SA et plus"))) -> 37 SA et plus | AA11: =RANK(B11,$B$2:$B$401,1)+(COUNTIF($B$2:$B$401,B11)-1)/2 -> 299 | AB11: =IF(AND(H11>=1,OR(I11="Oui",I11="Non")),1,0) -> 0
A12: F011 | B12: 21 | C12: Union libre | D12: Supérieur | E12: Commerçante | F12: Urbain | G12: 2 | H12: 1 | I12: Non | J12: Non | K12: Oui | L12: Non | M12: 34 | N12: 5 | O12: Unique | P12: 27.2 | Q12: 146 | R12: 89 | S12: Négative | T12: Non applicable | U12: HTA gestationnelle | V12: Non | W12: =IF(B12="","",IF(B12<=19,"Moins de 20 ans",IF(B12<=29,"20-29 ans",IF(B12<=34,"30-34 ans","35 ans et plus")))) -> 20-29 ans | X12: =IF(H12="","",IF(H12=0,"Nullipare (0)",IF(H12<=2,"1-2 accouchements","3 accouchements et plus"))) -> 1-2 accouchements | Y12: =IF(N12="","",IF(N12<=3,"Moins de 4 CPN",IF(N12<=7,"4 à 7 CPN","8 CPN et plus"))) -> 4 à 7 CPN | Z12: =IF(M12="","",IF(M12<=27,"20-27 SA",IF(M12<=36,"28-36 SA","37 SA et plus"))) -> 28-36 SA | AA12: =RANK(B12,$B$2:$B$401,1)+(COUNTIF($B$2:$B$401,B12)-1)/2 -> 48 | AB12: =IF(AND(H12>=1,OR(I12="Oui",I12="Non")),1,0) -> 1
A13: F012 | B13: 24 | C13: Mariée | D13: Primaire | E13: Artisane | F13: Rural | G13: 2 | H13: 1 | I13: Non | J13: Non | K13: Non | L13: Non | M13: 38 | N13: 3 | O13: Unique | P13: 24.4 | Q13: 151 | R13: 105 | S13: 1+ | T13: Oui | U13: Prééclampsie | V13: Oui | W13: =IF(B13="","",IF(B13<=19,"Moins de 20 ans",IF(B13<=29,"20-29 ans",IF(B13<=34,"30-34 ans","35 ans et plus")))) -> 20-29 ans | X13: =IF(H13="","",IF(H13=0,"Nullipare (0)",IF(H13<=2,"1-2 accouchements","3 accouchements et plus"))) -> 1-2 accouchements | Y13: =IF(N13="","",IF(N13<=3,"Moins de 4 CPN",IF(N13<=7,"4 à 7 CPN","8 CPN et plus"))) -> Moins de 4 CPN | Z13: =IF(M13="","",IF(M13<=27,"20-27 SA",IF(M13<=36,"28-36 SA","37 SA et plus"))) -> 37 SA et plus | AA13: =RANK(B13,$B$2:$B$401,1)+(COUNTIF($B$2:$B$401,B13)-1)/2 -> 139.5 | AB13: =IF(AND(H13>=1,OR(I13="Oui",I13="Non")),1,0) -> 1
A14: F013 | B14: 24 | C14: Mariée | D14: Primaire | E14: Commerçante | F14: Urbain | G14: 3 | H14: 1 | I14: Non | J14: Non | K14: Non | L14: Non | M14: 37 | N14: 5 | O14: Unique | P14: 23.2 | Q14: 98 | R14: 65 | S14: Négative | T14: Non applicable | U14: Normotendue | V14: Non | W14: =IF(B14="","",IF(B14<=19,"Moins de 20 ans",IF(B14<=29,"20-29 ans",IF(B14<=34,"30-34 ans","35 ans et plus")))) -> 20-29 ans | X14: =IF(H14="","",IF(H14=0,"Nullipare (0)",IF(H14<=2,"1-2 accouchements","3 accouchements et plus"))) -> 1-2 accouchements | Y14: =IF(N14="","",IF(N14<=3,"Moins de 4 CPN",IF(N14<=7,"4 à 7 CPN","8 CPN et plus"))) -> 4 à 7 CPN | Z14: =IF(M14="","",IF(M14<=27,"20-27 SA",IF(M14<=36,"28-36 SA","37 SA et plus"))) -> 37 SA et plus | AA14: =RANK(B14,$B$2:$B$401,1)+(COUNTIF($B$2:$B$401,B14)-1)/2 -> 139.5 | AB14: =IF(AND(H14>=1,OR(I14="Oui",I14="Non")),1,0) -> 1
A15: F014 | B15: 28 | C15: Mariée | D15: Primaire | E15: Commerçante | F15: Urbain | G15: 5 | H15: 4 | I15: Non | J15: Non | K15: Non | L15: Non | M15: 35 | N15: 8 | O15: Unique | P15: 20.5 | Q15: 144 | R15: 95 | S15: Négative | T15: Non applicable | U15: HTA gestationnelle | V15: Non | W15: =IF(B15="","",IF(B15<=19,"Moins de 20 ans",IF(B15<=29,"20-29 ans",IF(B15<=34,"30-34 ans","35 ans et plus")))) -> 20-29 ans | X15: =IF(H15="","",IF(H15=0,"Nullipare (0)",IF(H15<=2,"1-2 accouchements","3 accouchements et plus"))) -> 3 accouchements et plus | Y15: =IF(N15="","",IF(N15<=3,"Moins de 4 CPN",IF(N15<=7,"4 à 7 CPN","8 CPN et plus"))) -> 8 CPN et plus | Z15: =IF(M15="","",IF(M15<=27,"20-27 SA",IF(M15<=36,"28-36 SA","37 SA et plus"))) -> 28-36 SA | AA15: =RANK(B15,$B$2:$B$401,1)+(COUNTIF($B$2:$B$401,B15)-1)/2 -> 276 | AB15: =IF(AND(H15>=1,OR(I15="Oui",I15="Non")),1,0) -> 1
A16: F015 | B16: 27 | C16: Union libre | D16: Supérieur | E16: Ménagère | F16: Rural | G16: 4 | H16: 3 | I16: Non | J16: Non | K16: Non | L16: Non | M16: 29 | N16: 1 | O16: Unique | P16: 20.8 | Q16: 138 | R16: 98 | S16: 2+ | T16: Non | U16: Prééclampsie | V16: Oui | W16: =IF(B16="","",IF(B16<=19,"Moins de 20 ans",IF(B16<=29,"20-29 ans",IF(B16<=34,"30-34 ans","35 ans et plus")))) -> 20-29 ans | X16: =IF(H16="","",IF(H16=0,"Nullipare (0)",IF(H16<=2,"1-2 accouchements","3 accouchements et plus"))) -> 3 accouchements et plus | Y16: =IF(N16="","",IF(N16<=3,"Moins de 4 CPN",IF(N16<=7,"4 à 7 CPN","8 CPN et plus"))) -> Moins de 4 CPN | Z16: =IF(M16="","",IF(M16<=27,"20-27 SA",IF(M16<=36,"28-36 SA","37 SA et plus"))) -> 28-36 SA | AA16: =RANK(B16,$B$2:$B$401,1)+(COUNTIF($B$2:$B$401,B16)-1)/2 -> 243 | AB16: =IF(AND(H16>=1,OR(I16="Oui",I16="Non")),1,0) -> 1
A17: F016 | B17: 29 | C17: Mariée | D17: Supérieur | E17: Agricultrice | F17: Rural | G17: 3 | H17: 2 | I17: Non | J17: Non | K17: Non | L17: Non | M17: 39 | N17: 3 | O17: Unique | P17: 19.4 | Q17: 112 | R17: 75 | S17: Négative | T17: Non applicable | U17: Normotendue | V17: Non | W17: =IF(B17="","",IF(B17<=19,"Moins de 20 ans",IF(B17<=29,"20-29 ans",IF(B17<=34,"30-34 ans","35 ans et plus")))) -> 20-29 ans | X17: =IF(H17="","",IF(H17=0,"Nullipare (0)",IF(H17<=2,"1-2 accouchements","3 accouchements et plus"))) -> 1-2 accouchements | Y17: =IF(N17="","",IF(N17<=3,"Moins de 4 CPN",IF(N17<=7,"4 à 7 CPN","8 CPN et plus"))) -> Moins de 4 CPN | Z17: =IF(M17="","",IF(M17<=27,"20-27 SA",IF(M17<=36,"28-36 SA","37 SA et plus"))) -> 37 SA et plus | AA17: =RANK(B17,$B$2:$B$401,1)+(COUNTIF($B$2:$B$401,B17)-1)/2 -> 299 | AB17: =IF(AND(H17>=1,OR(I17="Oui",I17="Non")),1,0) -> 1
A18: F017 | B18: 31 | C18: Mariée | D18: Primaire | E18: Commerçante | F18: Urbain | G18: 7 | H18: 5 | I18: Oui | J18: Non | K18: Non | L18: Non | M18: 28 | N18: 3 | O18: Unique | P18: 25.1 | Q18: 104 | R18: 66 | S18: Négative | T18: Non applicable | U18: Normotendue | V18: Non | W18: =IF(B18="","",IF(B18<=19,"Moins de 20 ans",IF(B18<=29,"20-29 ans",IF(B18<=34,"30-34 ans","35 ans et plus")))) -> 30-34 ans | X18: =IF(H18="","",IF(H18=0,"Nullipare (0)",IF(H18<=2,"1-2 accouchements","3 accouchements et plus"))) -> 3 accouchements et plus | Y18: =IF(N18="","",IF(N18<=3,"Moins de 4 CPN",IF(N18<=7,"4 à 7 CPN","8 CPN et plus"))) -> Moins de 4 CPN | Z18: =IF(M18="","",IF(M18<=27,"20-27 SA",IF(M18<=36,"28-36 SA","37 SA et plus"))) -> 28-36 SA | AA18: =RANK(B18,$B$2:$B$401,1)+(COUNTIF($B$2:$B$401,B18)-1)/2 -> 334.5 | AB18: =IF(AND(H18>=1,OR(I18="Oui",I18="Non")),1,0) -> 1
A19: F018 | B19: 26 | C19: Mariée | D19: Primaire | E19: Agricultrice | F19: Rural | G19: 4 | H19: 3 | I19: Oui | J19: Non | K19: Non | L19: Non | M19: 37 | N19: 6 | O19: Unique | P19: 25.1 | Q19: 151 | R19: 91 | S19: Négative | T19: Oui | U19: Prééclampsie | V19: Oui | W19: =IF(B19="","",IF(B19<=19,"Moins de 20 ans",IF(B19<=29,"20-29 ans",IF(B19<=34,"30-34 ans","35 ans et plus")))) -> 20-29 ans | X19: =IF(H19="","",IF(H19=0,"Nullipare (0)",IF(H19<=2,"1-2 accouchements","3 accouchements et plus"))) -> 3 accouchements et plus | Y19: =IF(N19="","",IF(N19<=3,"Moins de 4 CPN",IF(N19<=7,"4 à 7 CPN","8 CPN et plus"))) -> 4 à 7 CPN | Z19: =IF(M19="","",IF(M19<=27,"20-27 SA",IF(M19<=36,"28-36 SA","37 SA et plus"))) -> 37 SA et plus | AA19: =RANK(B19,$B$2:$B$401,1)+(COUNTIF($B$2:$B$401,B19)-1)/2 -> 206 | AB19: =IF(AND(H19>=1,OR(I19="Oui",I19="Non")),1,0) -> 1
A20: F019 | B20: 27 | C20: Mariée | D20: Supérieur | E20: Commerçante | F20: Rural | G20: 4 | H20: 3 | I20: Non | J20: Non | K20: Non | L20: Non | M20: 30 | N20: 2 | O20: Unique | P20: 28.3 | Q20: 119 | R20: 71 | S20: Négative | T20: Non applicable | U20: Normotendue | V20: Non | W20: =IF(B20="","",IF(B20<=19,"Moins de 20 ans",IF(B20<=29,"20-29 ans",IF(B20<=34,"30-34 ans","35 ans et plus")))) -> 20-29 ans | X20: =IF(H20="","",IF(H20=0,"Nullipare (0)",IF(H20<=2,"1-2 accouchements","3 accouchements et plus"))) -> 3 accouchements et plus | Y20: =IF(N20="","",IF(N20<=3,"Moins de 4 CPN",IF(N20<=7,"4 à 7 CPN","8 CPN et plus"))) -> Moins de 4 CPN | Z20: =IF(M20="","",IF(M20<=27,"20-27 SA",IF(M20<=36,"28-36 SA","37 SA et plus"))) -> 28-36 SA | AA20: =RANK(B20,$B$2:$B$401,1)+(COUNTIF($B$2:$B$401,B20)-1)/2 -> 243 | AB20: =IF(AND(H20>=1,OR(I20="Oui",I20="Non")),1,0) -> 1
A21: F020 | B21: 23 | C21: Mariée | D21: Aucun | E21: Ménagère | F21: Rural | G21: 2 | H21: 1 | I21: Non | J21: Non | K21: Non | L21: Non | M21: 35 | N21: 4 | O21: Unique | P21: 21.6 | Q21: 104 | R21: 69 | S21: Négative | T21: Non applicable | U21: Normotendue | V21: Non | W21: =IF(B21="","",IF(B21<=19,"Moins de 20 ans",IF(B21<=29,"20-29 ans",IF(B21<=34,"30-34 ans","35 ans et plus")))) -> 20-29 ans | X21: =IF(H21="","",IF(H21=0,"Nullipare (0)",IF(H21<=2,"1-2 accouchements","3 accouchements et plus"))) -> 1-2 accouchements | Y21: =IF(N21="","",IF(N21<=3,"Moins de 4 CPN",IF(N21<=7,"4 à 7 CPN","8 CPN et plus"))) -> 4 à 7 CPN | Z21: =IF(M21="","",IF(M21<=27,"20-27 SA",IF(M21<=36,"28-36 SA","37 SA et plus"))) -> 28-36 SA | AA21: =RANK(B21,$B$2:$B$401,1)+(COUNTIF($B$2:$B$401,B21)-1)/2 -> 103.5 | AB21: =IF(AND(H21>=1,OR(I21="Oui",I21="Non")),1,0) -> 1
A22: F021 | B22: 27 | C22: Mariée | D22: Secondaire | E22: Artisane | F22: Urbain | G22: 3 | H22: 1 | I22: Non | J22: Non | K22: Oui | L22: Non | M22: 39 | N22: 4 | O22: Unique | P22: 27.3 | Q22: 104 | R22: 65 | S22: Traces | T22: Non applicable | U22: Normotendue | V22: Non | W22: =IF(B22="","",IF(B22<=19,"Moins de 20 ans",IF(B22<=29,"20-29 ans",IF(B22<=34,"30-34 ans","35 ans et plus")))) -> 20-29 ans | X22: =IF(H22="","",IF(H22=0,"Nullipare (0)",IF(H22<=2,"1-2 accouchements","3 accouchements et plus"))) -> 1-2 accouchements | Y22: =IF(N22="","",IF(N22<=3,"Moins de 4 CPN",IF(N22<=7,"4 à 7 CPN","8 CPN et plus"))) -> 4 à 7 CPN | Z22: =IF(M22="","",IF(M22<=27,"20-27 SA",IF(M22<=36,"28-36 SA","37 SA et plus"))) -> 37 SA et plus | AA22: =RANK(B22,$B$2:$B$401,1)+(COUNTIF($B$2:$B$401,B22)-1)/2 -> 243 | AB22: =IF(AND(H22>=1,OR(I22="Oui",I22="Non")),1,0) -> 1
... A28: F027 | B28: 21 | C28: Mariée | D28: Primaire | E28: Agricultrice | F28: Rural | G28: 3 | H28: 2 | I28: Non | J28: Oui | K28: Non | L28: Non | M28: 30 | N28: 3 | O28: Unique | P28: 26.5 | Q28: 150 | R28: 91 | S28: Négative | T28: Non applicable | U28: HTA chronique seule | V28: Non | W28: =IF(B28="","",IF(B28<=19,"Moins de 20 ans",IF(B28<=29,"20-29 ans",IF(B28<=34,"30-34 ans","35 ans et plus")))) -> 20-29 ans | X28: =IF(H28="","",IF(H28=0,"Nullipare (0)",IF(H28<=2,"1-2 accouchements","3 accouchements et plus"))) -> 1-2 accouchements | Y28: =IF(N28="","",IF(N28<=3,"Moins de 4 CPN",IF(N28<=7,"4 à 7 CPN","8 CPN et plus"))) -> Moins de 4 CPN | Z28: =IF(M28="","",IF(M28<=27,"20-27 SA",IF(M28<=36,"28-36 SA","37 SA et plus"))) -> 28-36 SA | AA28: =RANK(B28,$B$2:$B$401,1)+(COUNTIF($B$2:$B$401,B28)-1)/2 -> 48 | AB28: =IF(AND(H28>=1,OR(I28="Oui",I28="Non")),1,0) -> 1
A29: F028 | B29: 22 | C29: Union libre | D29: Primaire | E29: Agricultrice | F29: Rural | G29: 2 | H29: 1 | J29: Non | K29: Non | L29: Non | M29: 36 | N29: 1 | O29: Unique | P29: 23.1 | Q29: 104 | R29: 59 | S29: Négative | T29: Non applicable | U29: Normotendue | V29: Non | W29: =IF(B29="","",IF(B29<=19,"Moins de 20 ans",IF(B29<=29,"20-29 ans",IF(B29<=34,"30-34 ans","35 ans et plus")))) -> 20-29 ans | X29: =IF(H29="","",IF(H29=0,"Nullipare (0)",IF(H29<=2,"1-2 accouchements","3 accouchements et plus"))) -> 1-2 accouchements | Y29: =IF(N29="","",IF(N29<=3,"Moins de 4 CPN",IF(N29<=7,"4 à 7 CPN","8 CPN et plus"))) -> Moins de 4 CPN | Z29: =IF(M29="","",IF(M29<=27,"20-27 SA",IF(M29<=36,"28-36 SA","37 SA et plus"))) -> 28-36 SA | AA29: =RANK(B29,$B$2:$B$401,1)+(COUNTIF($B$2:$B$401,B29)-1)/2 -> 70 | AB29: =IF(AND(H29>=1,OR(I29="Oui",I29="Non")),1,0) -> 0
A30: F029 | B30: 27 | C30: Union libre | D30: Aucun | E30: Commerçante | F30: Urbain | G30: 4 | H30: 2 | I30: Non | J30: Non | K30: Oui | L30: Non | M30: 39 | N30: 5 | O30: Unique | P30: 30.6 | Q30: 115 | R30: 74 | S30: Négative | T30: Non applicable | U30: Normotendue | V30: Non | W30: =IF(B30="","",IF(B30<=19,"Moins de 20 ans",IF(B30<=29,"20-29 ans",IF(B30<=34,"30-34 ans","35 ans et plus")))) -> 20-29 ans | X30: =IF(H30="","",IF(H30=0,"Nullipare (0)",IF(H30<=2,"1-2 accouchements","3 accouchements et plus"))) -> 1-2 accouchements | Y30: =IF(N30="","",IF(N30<=3,"Moins de 4 CPN",IF(N30<=7,"4 à 7 CPN","8 CPN et plus"))) -> 4 à 7 CPN | Z30: =IF(M30="","",IF(M30<=27,"20-27 SA",IF(M30<=36,"28-36 SA","37 SA et plus"))) -> 37 SA et plus | AA30: =RANK(B30,$B$2:$B$401,1)+(COUNTIF($B$2:$B$401,B30)-1)/2 -> 243 | AB30: =IF(AND(H30>=1,OR(I30="Oui",I30="Non")),1,0) -> 1
A31: F030 | B31: 26 | C31: Union libre | D31: Secondaire | E31: Ménagère | F31: Rural | G31: 1 | H31: 0 | I31: Non applicable | J31: Non | K31: Non | L31: Non | M31: 30 | N31: 1 | O31: Unique | P31: 21.7 | Q31: 119 | R31: 80 | S31: Négative | T31: Non applicable | U31: Normotendue | V31: Non | W31: =IF(B31="","",IF(B31<=19,"Moins de 20 ans",IF(B31<=29,"20-29 ans",IF(B31<=34,"30-34 ans","35 ans et plus")))) -> 20-29 ans | X31: =IF(H31="","",IF(H31=0,"Nullipare (0)",IF(H31<=2,"1-2 accouchements","3 accouchements et plus"))) -> Nullipare (0) | Y31: =IF(N31="","",IF(N31<=3,"Moins de 4 CPN",IF(N31<=7,"4 à 7 CPN","8 CPN et plus"))) -> Moins de 4 CPN | Z31: =IF(M31="","",IF(M31<=27,"20-27 SA",IF(M31<=36,"28-36 SA","37 SA et plus"))) -> 28-36 SA | AA31: =RANK(B31,$B$2:$B$401,1)+(COUNTIF($B$2:$B$401,B31)-1)/2 -> 206 | AB31: =IF(AND(H31>=1,OR(I31="Oui",I31="Non")),1,0) -> 0
A32: F031 | B32: 25 | C32: Mariée | D32: Secondaire | E32: Commerçante | F32: Urbain | G32: 3 | H32: 2 | J32: Non | K32: Non | L32: Non | M32: 39 | N32: 2 | O32: Unique | P32: 29.7 | Q32: 110 | R32: 63 | S32: Traces | T32: Non applicable | U32: Normotendue | V32: Non | W32: =IF(B32="","",IF(B32<=19,"Moins de 20 ans",IF(B32<=29,"20-29 ans",IF(B32<=34,"30-34 ans","35 ans et plus")))) -> 20-29 ans | X32: =IF(H32="","",IF(H32=0,"Nullipare (0)",IF(H32<=2,"1-2 accouchements","3 accouchements et plus"))) -> 1-2 accouchements | Y32: =IF(N32="","",IF(N32<=3,"Moins de 4 CPN",IF(N32<=7,"4 à 7 CPN","8 CPN et plus"))) -> Moins de 4 CPN | Z32: =IF(M32="","",IF(M32<=27,"20-27 SA",IF(M32<=36,"28-36 SA","37 SA et plus"))) -> 37 SA et plus | AA32: =RANK(B32,$B$2:$B$401,1)+(COUNTIF($B$2:$B$401,B32)-1)/2 -> 173 | AB32: =IF(AND(H32>=1,OR(I32="Oui",I32="Non")),1,0) -> 0
A33: F032 | B33: 26 | C33: Mariée | D33: Supérieur | E33: Ménagère | F33: Rural | G33: 5 | H33: 4 | J33: Non | K33: Non | L33: Non | M33: 24 | N33: 2 | O33: Unique | P33: 25.4 | Q33: 121 | R33: 76 | S33: Négative | T33: Non applicable | U33: Normotendue | V33: Non | W33: =IF(B33="","",IF(B33<=19,"Moins de 20 ans",IF(B33<=29,"20-29 ans",IF(B33<=34,"30-34 ans","35 ans et plus")))) -> 20-29 ans | X33: =IF(H33="","",IF(H33=0,"Nullipare (0)",IF(H33<=2,"1-2 accouchements","3 accouchements et plus"))) -> 3 accouchements et plus | Y33: =IF(N33="","",IF(N33<=3,"Moins de 4 CPN",IF(N33<=7,"4 à 7 CPN","8 CPN et plus"))) -> Moins de 4 CPN | Z33: =IF(M33="","",IF(M33<=27,"20-27 SA",IF(M33<=36,"28-36 SA","37 SA et plus"))) -> 20-27 SA | AA33: =RANK(B33,$B$2:$B$401,1)+(COUNTIF($B$2:$B$401,B33)-1)/2 -> 206 | AB33: =IF(AND(H33>=1,OR(I33="Oui",I33="Non")),1,0) -> 0
A34: F033 | B34: 25 | C34: Mariée | D34: Primaire | E34: Commerçante | F34: Urbain | G34: 3 | H34: 2 | I34: Non | J34: Non | K34: Non | L34: Non | M34: 38 | N34: 1 | O34: Unique | P34: 27.6 | Q34: 119 | R34: 80 | S34: Négative | T34: Non applicable | U34: Normotendue | V34: Non | W34: =IF(B34="","",IF(B34<=19,"Moins de 20 ans",IF(B34<=29,"20-29 ans",IF(B34<=34,"30-34 ans","35 ans et plus")))) -> 20-29 ans | X34: =IF(H34="","",IF(H34=0,"Nullipare (0)",IF(H34<=2,"1-2 accouchements","3 accouchements et plus"))) -> 1-2 accouchements | Y34: =IF(N34="","",IF(N34<=3,"Moins de 4 CPN",IF(N34<=7,"4 à 7 CPN","8 CPN et plus"))) -> Moins de 4 CPN | Z34: =IF(M34="","",IF(M34<=27,"20-27 SA",IF(M34<=36,"28-36 SA","37 SA et plus"))) -> 37 SA et plus | AA34: =RANK(B34,$B$2:$B$401,1)+(COUNTIF($B$2:$B$401,B34)-1)/2 -> 173 | AB34: =IF(AND(H34>=1,OR(I34="Oui",I34="Non")),1,0) -> 1
A35: F034 | B35: 33 | C35: Mariée | D35: Secondaire | E35: Ménagère | F35: Rural | G35: 3 | H35: 2 | J35: Oui | K35: Non | L35: Non | M35: 34 | N35: 3 | O35: Unique | P35: 30.6 | Q35: 158 | R35: 98 | S35: Négative | T35: Non applicable | U35: HTA chronique seule | V35: Non | W35: =IF(B35="","",IF(B35<=19,"Moins de 20 ans",IF(B35<=29,"20-29 ans",IF(B35<=34,"30-34 ans","35 ans et plus")))) -> 30-34 ans | X35: =IF(H35="","",IF(H35=0,"Nullipare (0)",IF(H35<=2,"1-2 accouchements","3 accouchements et plus"))) -> 1-2 accouchements | Y35: =IF(N35="","",IF(N35<=3,"Moins de 4 CPN",IF(N35<=7,"4 à 7 CPN","8 CPN et plus"))) -> Moins de 4 CPN | Z35: =IF(M35="","",IF(M35<=27,"20-27 SA",IF(M35<=36,"28-36 SA","37 SA et plus"))) -> 28-36 SA | AA35: =RANK(B35,$B$2:$B$401,1)+(COUNTIF($B$2:$B$401,B35)-1)/2 -> 361.5 | AB35: =IF(AND(H35>=1,OR(I35="Oui",I35="Non")),1,0) -> 0
A36: F035 | B36: 23 | C36: Mariée | D36: Primaire | E36: Agricultrice | F36: Rural | G36: 2 | H36: 1 | I36: Non | J36: Non | K36: Non | L36: Non | M36: 37 | N36: 0 | O36: Unique | P36: 16.7 | Q36: 131 | R36: 74 | S36: Négative | T36: Non applicable | U36: Normotendue | V36: Non | W36: =IF(B36="","",IF(B36<=19,"Moins de 20 ans",IF(B36<=29,"20-29 ans",IF(B36<=34,"30-34 ans","35 ans et plus")))) -> 20-29 ans | X36: =IF(H36="","",IF(H36=0,"Nullipare (0)",IF(H36<=2,"1-2 accouchements","3 accouchements et plus"))) -> 1-2 accouchements | Y36: =IF(N36="","",IF(N36<=3,"Moins de 4 CPN",IF(N36<=7,"4 à 7 CPN","8 CPN et plus"))) -> Moins de 4 CPN | Z36: =IF(M36="","",IF(M36<=27,"20-27 SA",IF(M36<=36,"28-36 SA","37 SA et plus"))) -> 37 SA et plus | AA36: =RANK(B36,$B$2:$B$401,1)+(COUNTIF($B$2:$B$401,B36)-1)/2 -> 103.5 | AB36: =IF(AND(H36>=1,OR(I36="Oui",I36="Non")),1,0) -> 1
A37: F036 | B37: 25 | C37: Mariée | D37: Primaire | E37: Commerçante | F37: Rural | G37: 3 | H37: 1 | I37: Non | J37: Non | K37: Oui | L37: Non | M37: 35 | N37: 5 | O37: Unique | P37: 28.1 | Q37: 128 | R37: 73 | S37: Négative | T37: Non applicable | U37: Normotendue | V37: Non | W37: =IF(B37="","",IF(B37<=19,"Moins de 20 ans",IF(B37<=29,"20-29 ans",IF(B37<=34,"30-34 ans","35 ans et plus")))) -> 20-29 ans | X37: =IF(H37="","",IF(H37=0,"Nullipare (0)",IF(H37<=2,"1-2 accouchements","3 accouchements et plus"))) -> 1-2 accouchements | Y37: =IF(N37="","",IF(N37<=3,"Moins de 4 CPN",IF(N37<=7,"4 à 7 CPN","8 CPN et plus"))) -> 4 à 7 CPN | Z37: =IF(M37="","",IF(M37<=27,"20-27 SA",IF(M37<=36,"28-36 SA","37 SA et plus"))) -> 28-36 SA | AA37: =RANK(B37,$B$2:$B$401,1)+(COUNTIF($B$2:$B$401,B37)-1)/2 -> 173 | AB37: =IF(AND(H37>=1,OR(I37="Oui",I37="Non")),1,0) -> 1
A38: F037 | B38: 21 | C38: Célibataire | D38: Primaire | E38: Ménagère | F38: Rural | G38: 3 | H38: 2 | I38: Non | J38: Oui | K38: Non | L38: Non | M38: 30 | N38: 5 | O38: Unique | P38: 23.5 | Q38: 158 | R38: 100 | S38: Négative | T38: Non applicable | U38: HTA chronique seule | V38: Non | W38: =IF(B38="","",IF(B38<=19,"Moins de 20 ans",IF(B38<=29,"20-29 ans",IF(B38<=34,"30-34 ans","35 ans et plus")))) -> 20-29 ans | X38: =IF(H38="","",IF(H38=0,"Nullipare (0)",IF(H38<=2,"1-2 accouchements","3 accouchements et plus"))) -> 1-2 accouchements | Y38: =IF(N38="","",IF(N38<=3,"Moins de 4 CPN",IF(N38<=7,"4 à 7 CPN","8 CPN et plus"))) -> 4 à 7 CPN | Z38: =IF(M38="","",IF(M38<=27,"20-27 SA",IF(M38<=36,"28-36 SA","37 SA et plus"))) -> 28-36 SA | AA38: =RANK(B38,$B$2:$B$401,1)+(COUNTIF($B$2:$B$401,B38)-1)/2 -> 48 | AB38: =IF(AND(H38>=1,OR(I38="Oui",I38="Non")),1,0) -> 1
A39: F038 | B39: 28 | C39: Mariée | D39: Primaire | E39: Commerçante | F39: Urbain | G39: 4 | H39: 3 | I39: Non | J39: Non | K39: Non | L39: Non | M39: 30 | N39: 2 | O39: Unique | P39: 23 | Q39: 100 | R39: 61 | S39: Négative | T39: Non applicable | U39: Normotendue | V39: Non | W39: =IF(B39="","",IF(B39<=19,"Moins de 20 ans",IF(B39<=29,"20-29 ans",IF(B39<=34,"30-34 ans","35 ans et plus")))) -> 20-29 ans | X39: =IF(H39="","",IF(H39=0,"Nullipare (0)",IF(H39<=2,"1-2 accouchements","3 accouchements et plus"))) -> 3 accouchements et plus | Y39: =IF(N39="","",IF(N39<=3,"Moins de 4 CPN",IF(N39<=7,"4 à 7 CPN","8 CPN et plus"))) -> Moins de 4 CPN | Z39: =IF(M39="","",IF(M39<=27,"20-27 SA",IF(M39<=36,"28-36 SA","37 SA et plus"))) -> 28-36 SA | AA39: =RANK(B39,$B$2:$B$401,1)+(COUNTIF($B$2:$B$401,B39)-1)/2 -> 276 | AB39: =IF(AND(H39>=1,OR(I39="Oui",I39="Non")),1,0) -> 1
A40: F039 | B40: 22 | C40: Union libre | D40: Primaire | E40: Commerçante | F40: Urbain | G40: 1 | H40: 0 | I40: Non applicable | J40: Non | L40: Non | M40: 36 | N40: 2 | O40: Unique | P40: 22.5 | Q40: 117 | R40: 83 | S40: Négative | T40: Non applicable | U40: Normotendue | V40: Non | W40: =IF(B40="","",IF(B40<=19,"Moins de 20 ans",IF(B40<=29,"20-29 ans",IF(B40<=34,"30-34 ans","35 ans et plus")))) -> 20-29 ans | X40: =IF(H40="","",IF(H40=0,"Nullipare (0)",IF(H40<=2,"1-2 accouchements","3 accouchements et plus"))) -> Nullipare (0) | Y40: =IF(N40="","",IF(N40<=3,"Moins de 4 CPN",IF(N40<=7,"4 à 7 CPN","8 CPN et plus"))) -> Moins de 4 CPN | Z40: =IF(M40="","",IF(M40<=27,"20-27 SA",IF(M40<=36,"28-36 SA","37 SA et plus"))) -> 28-36 SA | AA40: =RANK(B40,$B$2:$B$401,1)+(COUNTIF($B$2:$B$401,B40)-1)/2 -> 70 | AB40: =IF(AND(H40>=1,OR(I40="Oui",I40="Non")),1,0) -> 0
A41: F040 | B41: 26 | C41: Célibataire | D41: Supérieur | E41: Élève/Étudiante | F41: Urbain | G41: 2 | H41: 0 | I41: Non applicable | J41: Non | K41: Non | L41: Non | M41: 39 | N41: 4 | O41: Multiple | P41: 21.4 | Q41: 108 | R41: 67 | S41: Négative | T41: Non applicable | U41: Normotendue | V41: Non | W41: =IF(B41="","",IF(B41<=19,"Moins de 20 ans",IF(B41<=29,"20-29 ans",IF(B41<=34,"30-34 ans","35 ans et plus")))) -> 20-29 ans | X41: =IF(H41="","",IF(H41=0,"Nullipare (0)",IF(H41<=2,"1-2 accouchements","3 accouchements et plus"))) -> Nullipare (0) | Y41: =IF(N41="","",IF(N41<=3,"Moins de 4 CPN",IF(N41<=7,"4 à 7 CPN","8 CPN et plus"))) -> 4 à 7 CPN | Z41: =IF(M41="","",IF(M41<=27,"20-27 SA",IF(M41<=36,"28-36 SA","37 SA et plus"))) -> 37 SA et plus | AA41: =RANK(B41,$B$2:$B$401,1)+(COUNTIF($B$2:$B$401,B41)-1)/2 -> 206 | AB41: =IF(AND(H41>=1,OR(I41="Oui",I41="Non")),1,0) -> 0
A42: F041 | B42: 26 | C42: Union libre | D42: Secondaire | E42: Commerçante | F42: Urbain | G42: 5 | H42: 4 | I42: Non | J42: Non | K42: Non | L42: Non | M42: 30 | N42: 3 | O42: Unique | P42: 25.9 | Q42: 105 | R42: 60 | S42: Négative | T42: Non applicable | U42: Normotendue | V42: Non | W42: =IF(B42="","",IF(B42<=19,"Moins de 20 ans",IF(B42<=29,"20-29 ans",IF(B42<=34,"30-34 ans","35 ans et plus")))) -> 20-29 ans | X42: =IF(H42="","",IF(H42=0,"Nullipare (0)",IF(H42<=2,"1-2 accouchements","3 accouchements et plus"))) -> 3 accouchements et plus | Y42: =IF(N42="","",IF(N42<=3,"Moins de 4 CPN",IF(N42<=7,"4 à 7 CPN","8 CPN et plus"))) -> Moins de 4 CPN | Z42: =IF(M42="","",IF(M42<=27,"20-27 SA",IF(M42<=36,"28-36 SA","37 SA et plus"))) -> 28-36 SA | AA42: =RANK(B42,$B$2:$B$401,1)+(COUNTIF($B$2:$B$401,B42)-1)/2 -> 206 | AB42: =IF(AND(H42>=1,OR(I42="Oui",I42="Non")),1,0) -> 1
A43: F042 | B43: 23 | C43: Union libre | D43: Secondaire | E43: Artisane | F43: Urbain | G43: 1 | H43: 0 | I43: Non applicable | J43: Non | K43: Non | L43: Non | M43: 29 | N43: 2 | O43: Unique | P43: 20.7 | Q43: 148 | R43: 89 | S43: 2+ | T43: Non | U43: Prééclampsie | V43: Oui | W43: =IF(B43="","",IF(B43<=19,"Moins de 20 ans",IF(B43<=29,"20-29 ans",IF(B43<=34,"30-34 ans","35 ans et plus")))) -> 20-29 ans | X43: =IF(H43="","",IF(H43=0,"Nullipare (0)",IF(H43<=2,"1-2 accouchements","3 accouchements et plus"))) -> Nullipare (0) | Y43: =IF(N43="","",IF(N43<=3,"Moins de 4 CPN",IF(N43<=7,"4 à 7 CPN","8 CPN et plus"))) -> Moins de 4 CPN | Z43: =IF(M43="","",IF(M43<=27,"20-27 SA",IF(M43<=36,"28-36 SA","37 SA et plus"))) -> 28-36 SA | AA43: =RANK(B43,$B$2:$B$401,1)+(COUNTIF($B$2:$B$401,B43)-1)/2 -> 103.5 | AB43: =IF(AND(H43>=1,OR(I43="Oui",I43="Non")),1,0) -> 0
A44: F043 | B44: 23 | C44: Mariée | D44: Primaire | E44: Commerçante | F44: Urbain | G44: 4 | H44: 2 | I44: Non | J44: Non | K44: Oui | L44: Non | M44: 34 | N44: 4 | O44: Unique | P44: 32.8 | Q44: 160 | R44: 102 | S44: 1+ | T44: Oui | U44: Prééclampsie | V44: Oui | W44: =IF(B44="","",IF(B44<=19,"Moins de 20 ans",IF(B44<=29,"20-29 ans",IF(B44<=34,"30-34 ans","35 ans et plus")))) -> 20-29 ans | X44: =IF(H44="","",IF(H44=0,"Nullipare (0)",IF(H44<=2,"1-2 accouchements","3 accouchements et plus"))) -> 1-2 accouchements | Y44: =IF(N44="","",IF(N44<=3,"Moins de 4 CPN",IF(N44<=7,"4 à 7 CPN","8 CPN et plus"))) -> 4 à 7 CPN | Z44: =IF(M44="","",IF(M44<=27,"20-27 SA",IF(M44<=36,"28-36 SA","37 SA et plus"))) -> 28-36 SA | AA44: =RANK(B44,$B$2:$B$401,1)+(COUNTIF($B$2:$B$401,B44)-1)/2 -> 103.5 | AB44: =IF(AND(H44>=1,OR(I44="Oui",I44="Non")),1,0) -> 1
A45: F044 | B45: 20 | C45: Célibataire | D45: Aucun | E45: Ménagère | F45: Urbain | G45: 1 | H45: 0 | I45: Non applicable | J45: Non | K45: Non | L45: Non | M45: 37 | N45: 7 | O45: Unique | P45: 23.1 | Q45: 117 | R45: 78 | S45: 1+ | T45: Non applicable | U45: Normotendue | V45: Non | W45: =IF(B45="","",IF(B45<=19,"Moins de 20 ans",IF(B45<=29,"20-29 ans",IF(B45<=34,"30-34 ans","35 ans et plus")))) -> 20-29 ans | X45: =IF(H45="","",IF(H45=0,"Nullipare (0)",IF(H45<=2,"1-2 accouchements","3 accouchements et plus"))) -> Nullipare (0) | Y45: =IF(N45="","",IF(N45<=3,"Moins de 4 CPN",IF(N45<=7,"4 à 7 CPN","8 CPN et plus"))) -> 4 à 7 CPN | Z45: =IF(M45="","",IF(M45<=27,"20-27 SA",IF(M45<=36,"28-36 SA","37 SA et plus"))) -> 37 SA et plus | AA45: =RANK(B45,$B$2:$B$401,1)+(COUNTIF($B$2:$B$401,B45)-1)/2 -> 30.5 | AB45: =IF(AND(H45>=1,OR(I45="Oui",I45="Non")),1,0) -> 0
...

Sheet Dictionnaire
A1: Dictionnaire des variables
A2: Données entièrement synthétiques (fictives) – usage pédagogique exclusivement
A4: Colonne | B4: Variable | C4: Signification | D4: Type statistique | E4: Unité | F4: Codage / modalités | G4: Valeurs manquantes (formule) | H4: Signification des manquants
A5: A | B5: id_patiente | C5: Identifiant anonymisé de la patiente (fictif) | D5: Qualitative (identifiant) | E5: – | F5: F001 à F400 | G5: =COUNTBLANK(Donnees!$A$2:$A$401) -> 0 | H5: –
A6: B | B6: age_ans | C6: Âge de la femme à l'inclusion | D6: Quantitative discrète | E6: années | F6: Nombre entier (observé : 17 à 45) | G6: =COUNTBLANK(Donnees!$B$2:$B$401) -> 0 | H6: –
A7: C | B7: situation_matrimoniale | C7: Situation matrimoniale | D7: Qualitative nominale | E7: – | F7: Mariée ; Union libre ; Célibataire ; Veuve/divorcée | G7: =COUNTBLANK(Donnees!$C$2:$C$401) -> 0 | H7: –
A8: D | B8: niveau_instruction | C8: Plus haut niveau d'études atteint | D8: Qualitative ordinale | E8: – | F8: Aucun ; Primaire ; Secondaire ; Supérieur | G8: =COUNTBLANK(Donnees!$D$2:$D$401) -> 6 | H8: non renseigné
A9: E | B9: profession | C9: Profession principale | D9: Qualitative nominale | E9: – | F9: Ménagère ; Commerçante ; Agricultrice ; Élève/Étudiante ; Artisane ; Salariée | G9: =COUNTBLANK(Donnees!$E$2:$E$401) -> 8 | H9: non renseignée
A10: F | B10: milieu_residence | C10: Milieu de résidence | D10: Qualitative nominale (2 modalités) | E10: – | F10: Urbain ; Rural | G10: =COUNTBLANK(Donnees!$F$2:$F$401) -> 0 | H10: –
A11: G | B11: gestite | C11: Nombre total de grossesses, y compris la grossesse actuelle et les pertes (fausses couches, avortements) | D11: Quantitative discrète | E11: nombre | F11: 1, 2, 3 … (toujours ≥ parité + 1) | G11: =COUNTBLANK(Donnees!$G$2:$G$401) -> 0 | H11: –
A12: H | B12: parite | C12: Nombre d'accouchements antérieurs (≥ 28 SA). La grossesse actuelle n'est pas comptée | D12: Quantitative discrète | E12: nombre | F12: 0 = nullipare ; 1, 2, 3 … | G12: =COUNTBLANK(Donnees!$H$2:$H$401) -> 0 | H12: –
A13: I | B13: atcd_preeclampsie | C13: Antécédent personnel de prééclampsie lors d'une grossesse précédente | D13: Qualitative nominale | E13: – | F13: Oui ; Non ; Non applicable (aucune grossesse antérieure : parité = 0) | G13: =COUNTBLANK(Donnees!$I$2:$I$401) -> 6 | H13: information non retrouvée dans le dossier (femmes déjà accouchées)
A14: J | B14: atcd_hta_chronique | C14: HTA connue avant la grossesse (ou avant 20 SA) | D14: Qualitative nominale (2 modalités) | E14: – | F14: Oui ; Non | G14: =COUNTBLANK(Donnees!$J$2:$J$401) -> 0 | H14: –
A15: K | B15: atcd_familial_hta | C15: Antécédent familial d'HTA (mère ou sœur) | D15: Qualitative nominale (2 modalités) | E15: – | F15: Oui ; Non | G15: =COUNTBLANK(Donnees!$K$2:$K$401) -> 12 | H15: non renseigné
A16: L | B16: atcd_diabete | C16: Diabète connu avant la grossesse | D16: Qualitative nominale (2 modalités) | E16: – | F16: Oui ; Non | G16: =COUNTBLANK(Donnees!$L$2:$L$401) -> 5 | H16: non renseigné
A17: M | B17: age_gestationnel_sa | C17: Âge gestationnel au moment du diagnostic ou de la dernière consultation | D17: Quantitative discrète | E17: semaines d'aménorrhée (SA) | F17: 20 à 41 | G17: =COUNTBLANK(Donnees!$M$2:$M$401) -> 0 | H17: –
A18: N | B18: nb_cpn | C18: Nombre de consultations prénatales (CPN) effectuées | D18: Quantitative discrète | E18: nombre | F18: 0 à 10 | G18: =COUNTBLANK(Donnees!$N$2:$N$401) -> 10 | H18: non renseigné
A19: O | B19: type_grossesse | C19: Type de grossesse | D19: Qualitative nominale (2 modalités) | E19: – | F19: Unique ; Multiple | G19: =COUNTBLANK(Donnees!$O$2:$O$401) -> 0 | H19: –
A20: P | B20: imc | C20: Indice de masse corporelle à la 1re consultation prénatale | D20: Quantitative continue | E20: kg/m² | F20: Nombre décimal (observé : 16,0 à 36,2) | G20: =COUNTBLANK(Donnees!$P$2:$P$401) -> 30 | H20: poids ou taille non mesuré
A21: Q | B21: pas_mmhg | C21: Pression artérielle systolique retenue pour le diagnostic (valeur confirmée) | D21: Quantitative discrète | E21: mmHg | F21: Nombre entier | G21: =COUNTBLANK(Donnees!$Q$2:$Q$401) -> 0 | H21: –
A22: R | B22: pad_mmhg | C22: Pression artérielle diastolique retenue pour le diagnostic (valeur confirmée) | D22: Quantitative discrète | E22: mmHg | F22: Nombre entier | G22: =COUNTBLANK(Donnees!$R$2:$R$401) -> 0 | H22: –
A23: S | B23: proteinurie | C23: Protéinurie à la bandelette urinaire | D23: Qualitative ordinale | E23: – | F23: Négative ; Traces ; 1+ ; 2+ ; 3+ (≥ 1+ = positive) | G23: =COUNTBLANK(Donnees!$S$2:$S$401) -> 0 | H23: –
A24: T | B24: signes_gravite | C24: Présence d'un signe de gravité : PA ≥ 160/110 mmHg ou signe clinique/biologique d'atteinte d'organe (céphalées persistantes, troubles visuels, douleur épigastrique, etc.) | D24: Qualitative nominale | E24: – | F24: Oui ; Non ; Non applicable (femme sans prééclampsie) | G24: =COUNTBLANK(Donnees!$T$2:$T$401) -> 0 | H24: –
A25: U | B25: type_diagnostic | C25: Diagnostic final retenu (5 catégories exclusives) | D25: Qualitative nominale | E25: – | F25: Normotendue ; HTA gestationnelle ; HTA chronique seule ; Prééclampsie ; Prééclampsie surajoutée | G25: =COUNTBLANK(Donnees!$U$2:$U$401) -> 0 | H25: –
A26: V | B26: preeclampsie | C26: VARIABLE PRINCIPALE. Prééclampsie, toutes formes confondues (= Prééclampsie ou Prééclampsie surajoutée) | D26: Qualitative nominale (2 modalités) | E26: – | F26: Oui ; Non | G26: =COUNTBLANK(Donnees!$V$2:$V$401) -> 0 | H26: –
A28: Une cellule vide dans la feuille Donnees correspond à NA (donnée manquante). « Non applicable » est une vraie modalité, à ne pas confondre avec une donnée manquante.

Sheet 1_Exploration
A1: Section 2 – Exploration du jeu de données
A2: Équivalent de dim(), names(), str(), summary(), colSums(is.na()) et head() dans R
A4: Dimensions du jeu de données (dim)
A5: Nombre d'observations (femmes) | B5: =COUNTA(Donnees!$A$2:$A$401) -> 400
A6: Nombre de variables (colonnes d'origine) | B6: =COUNTA(Donnees!$A$1:$V$1) -> 22
A8: Variables, type et valeurs manquantes (names, str, colSums(is.na))
A9: Variable | B9: Type | C9: Effectif renseigné | D9: Valeurs manquantes | E9: % manquant
A10: id_patiente | B10: Qualitative (identifiant) | C10: =COUNTA(Donnees!$A$2:$A$401) -> 400 | D10: =COUNTBLANK(Donnees!$A$2:$A$401) -> 0 | E10: =D10/$B$5*100 -> 0
A11: age_ans | B11: Quantitative discrète | C11: =COUNTA(Donnees!$B$2:$B$401) -> 400 | D11: =COUNTBLANK(Donnees!$B$2:$B$401) -> 0 | E11: =D11/$B$5*100 -> 0
A12: situation_matrimoniale | B12: Qualitative nominale | C12: =COUNTA(Donnees!$C$2:$C$401) -> 400 | D12: =COUNTBLANK(Donnees!$C$2:$C$401) -> 0 | E12: =D12/$B$5*100 -> 0
A13: niveau_instruction | B13: Qualitative ordinale | C13: =COUNTA(Donnees!$D$2:$D$401) -> 394 | D13: =COUNTBLANK(Donnees!$D$2:$D$401) -> 6 | E13: =D13/$B$5*100 -> 1.5
A14: profession | B14: Qualitative nominale | C14: =COUNTA(Donnees!$E$2:$E$401) -> 392 | D14: =COUNTBLANK(Donnees!$E$2:$E$401) -> 8 | E14: =D14/$B$5*100 -> 2
A15: milieu_residence | B15: Qualitative nominale (2 modalités) | C15: =COUNTA(Donnees!$F$2:$F$401) -> 400 | D15: =COUNTBLANK(Donnees!$F$2:$F$401) -> 0 | E15: =D15/$B$5*100 -> 0
A16: gestite | B16: Quantitative discrète | C16: =COUNTA(Donnees!$G$2:$G$401) -> 400 | D16: =COUNTBLANK(Donnees!$G$2:$G$401) -> 0 | E16: =D16/$B$5*100 -> 0
A17: parite | B17: Quantitative discrète | C17: =COUNTA(Donnees!$H$2:$H$401) -> 400 | D17: =COUNTBLANK(Donnees!$H$2:$H$401) -> 0 | E17: =D17/$B$5*100 -> 0
A18: atcd_preeclampsie | B18: Qualitative nominale | C18: =COUNTA(Donnees!$I$2:$I$401) -> 394 | D18: =COUNTBLANK(Donnees!$I$2:$I$401) -> 6 | E18: =D18/$B$5*100 -> 1.5
A19: atcd_hta_chronique | B19: Qualitative nominale (2 modalités) | C19: =COUNTA(Donnees!$J$2:$J$401) -> 400 | D19: =COUNTBLANK(Donnees!$J$2:$J$401) -> 0 | E19: =D19/$B$5*100 -> 0
A20: atcd_familial_hta | B20: Qualitative nominale (2 modalités) | C20: =COUNTA(Donnees!$K$2:$K$401) -> 388 | D20: =COUNTBLANK(Donnees!$K$2:$K$401) -> 12 | E20: =D20/$B$5*100 -> 3
A21: atcd_diabete | B21: Qualitative nominale (2 modalités) | C21: =COUNTA(Donnees!$L$2:$L$401) -> 395 | D21: =COUNTBLANK(Donnees!$L$2:$L$401) -> 5 | E21: =D21/$B$5*100 -> 1.25
A22: age_gestationnel_sa | B22: Quantitative discrète | C22: =COUNTA(Donnees!$M$2:$M$401) -> 400 | D22: =COUNTBLANK(Donnees!$M$2:$M$401) -> 0 | E22: =D22/$B$5*100 -> 0
A23: nb_cpn | B23: Quantitative discrète | C23: =COUNTA(Donnees!$N$2:$N$401) -> 390 | D23: =COUNTBLANK(Donnees!$N$2:$N$401) -> 10 | E23: =D23/$B$5*100 -> 2.5
A24: type_grossesse | B24: Qualitative nominale (2 modalités) | C24: =COUNTA(Donnees!$O$2:$O$401) -> 400 | D24: =COUNTBLANK(Donnees!$O$2:$O$401) -> 0 | E24: =D24/$B$5*100 -> 0
A25: imc | B25: Quantitative continue | C25: =COUNTA(Donnees!$P$2:$P$401) -> 370 | D25: =COUNTBLANK(Donnees!$P$2:$P$401) -> 30 | E25: =D25/$B$5*100 -> 7.5
A26: pas_mmhg | B26: Quantitative discrète | C26: =COUNTA(Donnees!$Q$2:$Q$401) -> 400 | D26: =COUNTBLANK(Donnees!$Q$2:$Q$401) -> 0 | E26: =D26/$B$5*100 -> 0
A27: pad_mmhg | B27: Quantitative discrète | C27: =COUNTA(Donnees!$R$2:$R$401) -> 400 | D27: =COUNTBLANK(Donnees!$R$2:$R$401) -> 0 | E27: =D27/$B$5*100 -> 0
A28: proteinurie | B28: Qualitative ordinale | C28: =COUNTA(Donnees!$S$2:$S$401) -> 400 | D28: =COUNTBLANK(Donnees!$S$2:$S$401) -> 0 | E28: =D28/$B$5*100 -> 0
A29: signes_gravite | B29: Qualitative nominale | C29: =COUNTA(Donnees!$T$2:$T$401) -> 400 | D29: =COUNTBLANK(Donnees!$T$2:$T$401) -> 0 | E29: =D29/$B$5*100 -> 0
A30: type_diagnostic | B30: Qualitative nominale | C30: =COUNTA(Donnees!$U$2:$U$401) -> 400 | D30: =COUNTBLANK(Donnees!$U$2:$U$401) -> 0 | E30: =D30/$B$5*100 -> 0
A31: preeclampsie | B31: Qualitative nominale (2 modalités) | C31: =COUNTA(Donnees!$V$2:$V$401) -> 400 | D31: =COUNTBLANK(Donnees!$V$2:$V$401) -> 0 | E31: =D31/$B$5*100 -> 0
A33: Résumé des variables quantitatives (summary)
A34: Variable | B34: N valides | C34: Minimum | D34: 1er quartile | E34: Médiane | F34: Moyenne | G34: 3e quartile | H34: Maximum
A35: age_ans | B35: =COUNT(Donnees!$B$2:$B$401) -> 400 | C35: =MIN(Donnees!$B$2:$B$401) -> 17 | D35: =QUARTILE(Donnees!$B$2:$B$401,1) -> 23 | E35: =MEDIAN(Donnees!$B$2:$B$401) -> 26 | F35: =AVERAGE(Donnees!$B$2:$B$401) -> 26.405 | G35: =QUARTILE(Donnees!$B$2:$B$401,3) -> 29 | H35: =MAX(Donnees!$B$2:$B$401) -> 45
A36: gestite | B36: =COUNT(Donnees!$G$2:$G$401) -> 400 | C36: =MIN(Donnees!$G$2:$G$401) -> 1 | D36: =QUARTILE(Donnees!$G$2:$G$401,1) -> 2 | E36: =MEDIAN(Donnees!$G$2:$G$401) -> 2 | F36: =AVERAGE(Donnees!$G$2:$G$401) -> 2.7475 | G36: =QUARTILE(Donnees!$G$2:$G$401,3) -> 4 | H36: =MAX(Donnees!$G$2:$G$401) -> 10
A37: parite | B37: =COUNT(Donnees!$H$2:$H$401) -> 400 | C37: =MIN(Donnees!$H$2:$H$401) -> 0 | D37: =QUARTILE(Donnees!$H$2:$H$401,1) -> 0 | E37: =MEDIAN(Donnees!$H$2:$H$401) -> 1 | F37: =AVERAGE(Donnees!$H$2:$H$401) -> 1.5725 | G37: =QUARTILE(Donnees!$H$2:$H$401,3) -> 2 | H37: =MAX(Donnees!$H$2:$H$401) -> 8
A38: age_gestationnel_sa | B38: =COUNT(Donnees!$M$2:$M$401) -> 400 | C38: =MIN(Donnees!$M$2:$M$401) -> 21 | D38: =QUARTILE(Donnees!$M$2:$M$401,1) -> 32 | E38: =MEDIAN(Donnees!$M$2:$M$401) -> 35 | F38: =AVERAGE(Donnees!$M$2:$M$401) -> 34.3675 | G38: =QUARTILE(Donnees!$M$2:$M$401,3) -> 38 | H38: =MAX(Donnees!$M$2:$M$401) -> 41
A39: nb_cpn | B39: =COUNT(Donnees!$N$2:$N$401) -> 390 | C39: =MIN(Donnees!$N$2:$N$401) -> 0 | D39: =QUARTILE(Donnees!$N$2:$N$401,1) -> 2 | E39: =MEDIAN(Donnees!$N$2:$N$401) -> 3 | F39: =AVERAGE(Donnees!$N$2:$N$401) -> 3.5948718 | G39: =QUARTILE(Donnees!$N$2:$N$401,3) -> 5 | H39: =MAX(Donnees!$N$2:$N$401) -> 10
A40: imc | B40: =COUNT(Donnees!$P$2:$P$401) -> 370 | C40: =MIN(Donnees!$P$2:$P$401) -> 16 | D40: =QUARTILE(Donnees!$P$2:$P$401,1) -> 21.4 | E40: =MEDIAN(Donnees!$P$2:$P$401) -> 23.85 | F40: =AVERAGE(Donnees!$P$2:$P$401) -> 24.169459 | G40: =QUARTILE(Donnees!$P$2:$P$401,3) -> 26.5 | H40: =MAX(Donnees!$P$2:$P$401) -> 36.2
A41: pas_mmhg | B41: =COUNT(Donnees!$Q$2:$Q$401) -> 400 | C41: =MIN(Donnees!$Q$2:$Q$401) -> 90 | D41: =QUARTILE(Donnees!$Q$2:$Q$401,1) -> 106 | E41: =MEDIAN(Donnees!$Q$2:$Q$401) -> 112 | F41: =AVERAGE(Donnees!$Q$2:$Q$401) -> 117.51 | G41: =QUARTILE(Donnees!$Q$2:$Q$401,3) -> 121 | H41: =MAX(Donnees!$Q$2:$Q$401) -> 180
A42: pad_mmhg | B42: =COUNT(Donnees!$R$2:$R$401) -> 400 | C42: =MIN(Donnees!$R$2:$R$401) -> 52 | D42: =QUARTILE(Donnees!$R$2:$R$401,1) -> 66 | E42: =MEDIAN(Donnees!$R$2:$R$401) -> 70 | F42: =AVERAGE(Donnees!$R$2:$R$401) -> 73.4125 | G42: =QUARTILE(Donnees!$R$2:$R$401,3) -> 76 | H42: =MAX(Donnees!$R$2:$R$401) -> 110
A44: Aperçu des 6 premières patientes (head)
...

Sheet 2_Description
A1: Partie A – Description de la population (Questions 1 à 3)
A2: Les pourcentages sont calculés sur les effectifs valides (hors données manquantes)
A4: QUESTION 1 : Quel est l'âge moyen des femmes enceintes incluses dans l'étude ?
A5: Statistique | B5: Valeur | D5: Histogramme (Graphique 1) : effectifs par classe d'âge
A6: Effectif valide | B6: =COUNT(Donnees!$B$2:$B$401) -> 400 | D6: Classe (ans) | E6: Borne basse (exclue) | F6: Borne haute (incluse) | G6: Effectif
A7: Moyenne | B7: =AVERAGE(Donnees!$B$2:$B$401) -> 26.405 | D7: =(E7+1)&"-"&F7 -> 15-16 | E7: 14 | F7: =E7+2 -> 16 | G7: =COUNTIFS(Donnees!$B$2:$B$401,">"&E7,Donnees!$B$2:$B$401,"<="&F7) -> 0
A8: Écart-type | B8: =STDEV(Donnees!$B$2:$B$401) -> 4.9413579 | D8: =(E8+1)&"-"&F8 -> 17-18 | E8: 16 | F8: =E8+2 -> 18 | G8: =COUNTIFS(Donnees!$B$2:$B$401,">"&E8,Donnees!$B$2:$B$401,"<="&F8) -> 7
A9: Médiane | B9: =MEDIAN(Donnees!$B$2:$B$401) -> 26 | D9: =(E9+1)&"-"&F9 -> 19-20 | E9: 18 | F9: =E9+2 -> 20 | G9: =COUNTIFS(Donnees!$B$2:$B$401,">"&E9,Donnees!$B$2:$B$401,"<="&F9) -> 32
A10: Minimum | B10: =MIN(Donnees!$B$2:$B$401) -> 17 | D10: =(E10+1)&"-"&F10 -> 21-22 | E10: 20 | F10: =E10+2 -> 22 | G10: =COUNTIFS(Donnees!$B$2:$B$401,">"&E10,Donnees!$B$2:$B$401,"<="&F10) -> 44
A11: Maximum | B11: =MAX(Donnees!$B$2:$B$401) -> 45 | D11: =(E11+1)&"-"&F11 -> 23-24 | E11: 22 | F11: =E11+2 -> 24 | G11: =COUNTIFS(Donnees!$B$2:$B$401,">"&E11,Donnees!$B$2:$B$401,"<="&F11) -> 72
A12: ="Âge moyen : "&FIXED(B7,1)&" ans (écart-type : "&FIXED(B8,1)&"). Médiane : "&B9&" ans ; minimum : "&B10&" ; maximum : "&B11&"." -> Âge moyen : 26,4 ans (écart-type : 4,9). Médiane : 26 ans ; minimum : 17 ; maximum : 45. | D12: =(E12+1)&"-"&F12 -> 25-26 | E12: 24 | F12: =E12+2 -> 26 | G12: =COUNTIFS(Donnees!$B$2:$B$401,">"&E12,Donnees!$B$2:$B$401,"<="&F12) -> 66
D13: =(E13+1)&"-"&F13 -> 27-28 | E13: 26 | F13: =E13+2 -> 28 | G13: =COUNTIFS(Donnees!$B$2:$B$401,">"&E13,Donnees!$B$2:$B$401,"<="&F13) -> 66
D14: =(E14+1)&"-"&F14 -> 29-30 | E14: 28 | F14: =E14+2 -> 30 | G14: =COUNTIFS(Donnees!$B$2:$B$401,">"&E14,Donnees!$B$2:$B$401,"<="&F14) -> 41
D15: =(E15+1)&"-"&F15 -> 31-32 | E15: 30 | F15: =E15+2 -> 32 | G15: =COUNTIFS(Donnees!$B$2:$B$401,">"&E15,Donnees!$B$2:$B$401,"<="&F15) -> 26
D16: =(E16+1)&"-"&F16 -> 33-34 | E16: 32 | F16: =E16+2 -> 34 | G16: =COUNTIFS(Donnees!$B$2:$B$401,">"&E16,Donnees!$B$2:$B$401,"<="&F16) -> 21
D17: =(E17+1)&"-"&F17 -> 35-36 | E17: 34 | F17: =E17+2 -> 36 | G17: =COUNTIFS(Donnees!$B$2:$B$401,">"&E17,Donnees!$B$2:$B$401,"<="&F17) -> 10
D18: =(E18+1)&"-"&F18 -> 37-38 | E18: 36 | F18: =E18+2 -> 38 | G18: =COUNTIFS(Donnees!$B$2:$B$401,">"&E18,Donnees!$B$2:$B$401,"<="&F18) -> 5
D19: =(E19+1)&"-"&F19 -> 39-40 | E19: 38 | F19: =E19+2 -> 40 | G19: =COUNTIFS(Donnees!$B$2:$B$401,">"&E19,Donnees!$B$2:$B$401,"<="&F19) -> 4
D20: =(E20+1)&"-"&F20 -> 41-42 | E20: 40 | F20: =E20+2 -> 42 | G20: =COUNTIFS(Donnees!$B$2:$B$401,">"&E20,Donnees!$B$2:$B$401,"<="&F20) -> 3
D21: =(E21+1)&"-"&F21 -> 43-44 | E21: 42 | F21: =E21+2 -> 44 | G21: =COUNTIFS(Donnees!$B$2:$B$401,">"&E21,Donnees!$B$2:$B$401,"<="&F21) -> 1
D22: =(E22+1)&"-"&F22 -> 45-46 | E22: 44 | F22: =E22+2 -> 46 | G22: =COUNTIFS(Donnees!$B$2:$B$401,">"&E22,Donnees!$B$2:$B$401,"<="&F22) -> 2
D23: Total | G23: =SUM(G7:G22) -> 400
A24: QUESTION 2 : Quelles sont les principales caractéristiques sociodémographiques ? → Tableau 1
A25: Variable | B25: Modalité | C25: Effectif | D25: Pourcentage (%)
A26: Tranche d'âge | B26: Moins de 20 ans | C26: =COUNTIF(Donnees!$W$2:$W$401,B26) -> 21 | D26: =C26/SUM($C$26:$C$29)*100 -> 5.25
B27: 20-29 ans | C27: =COUNTIF(Donnees!$W$2:$W$401,B27) -> 289 | D27: =C27/SUM($C$26:$C$29)*100 -> 72.25
B28: 30-34 ans | C28: =COUNTIF(Donnees!$W$2:$W$401,B28) -> 65 | D28: =C28/SUM($C$26:$C$29)*100 -> 16.25
B29: 35 ans et plus | C29: =COUNTIF(Donnees!$W$2:$W$401,B29) -> 25 | D29: =C29/SUM($C$26:$C$29)*100 -> 6.25
A30: Situation matrimoniale | B30: Célibataire | C30: =COUNTIF(Donnees!$C$2:$C$401,B30) -> 68 | D30: =C30/SUM($C$30:$C$33)*100 -> 17
B31: Mariée | C31: =COUNTIF(Donnees!$C$2:$C$401,B31) -> 255 | D31: =C31/SUM($C$30:$C$33)*100 -> 63.75
B32: Union libre | C32: =COUNTIF(Donnees!$C$2:$C$401,B32) -> 69 | D32: =C32/SUM($C$30:$C$33)*100 -> 17.25
B33: Veuve/divorcée | C33: =COUNTIF(Donnees!$C$2:$C$401,B33) -> 8 | D33: =C33/SUM($C$30:$C$33)*100 -> 2
A34: Niveau d'instruction | B34: Aucun | C34: =COUNTIF(Donnees!$D$2:$D$401,B34) -> 53 | D34: =C34/SUM($C$34:$C$37)*100 -> 13.451777
B35: Primaire | C35: =COUNTIF(Donnees!$D$2:$D$401,B35) -> 121 | D35: =C35/SUM($C$34:$C$37)*100 -> 30.71066
B36: Secondaire | C36: =COUNTIF(Donnees!$D$2:$D$401,B36) -> 177 | D36: =C36/SUM($C$34:$C$37)*100 -> 44.923858
B37: Supérieur | C37: =COUNTIF(Donnees!$D$2:$D$401,B37) -> 43 | D37: =C37/SUM($C$34:$C$37)*100 -> 10.913706
B38: Données manquantes | C38: =COUNTBLANK(Donnees!$D$2:$D$401) -> 6
A39: Profession | B39: Agricultrice | C39: =COUNTIF(Donnees!$E$2:$E$401,B39) -> 51 | D39: =C39/SUM($C$39:$C$44)*100 -> 13.010204
B40: Artisane | C40: =COUNTIF(Donnees!$E$2:$E$401,B40) -> 42 | D40: =C40/SUM($C$39:$C$44)*100 -> 10.714286
B41: Commerçante | C41: =COUNTIF(Donnees!$E$2:$E$401,B41) -> 125 | D41: =C41/SUM($C$39:$C$44)*100 -> 31.887755
...

Sheet 3_Frequence
A1: Partie B – Fréquence de la prééclampsie (Question 4)
A3: QUESTION 4 : Quelle est la proportion de femmes présentant une prééclampsie ? → Tableau 3
A4: Variable | B4: Modalité | C4: Effectif | D4: Pourcentage (%) | G4: Données du Graphique 2
A5: Prééclampsie (toutes formes) | B5: Non | C5: =COUNTIF(Donnees!$V$2:$V$401,B5) -> 352 | D5: =C5/SUM($C$5:$C$6)*100 -> 88 | G5: Statut | H5: Effectif
B6: Oui | C6: =COUNTIF(Donnees!$V$2:$V$401,B6) -> 48 | D6: =C6/SUM($C$5:$C$6)*100 -> 12 | G6: Prééclampsie | H6: =C6 -> 48
A7: Type de diagnostic | B7: Normotendue | C7: =COUNTIF(Donnees!$U$2:$U$401,B7) -> 327 | D7: =C7/SUM($C$7:$C$11)*100 -> 81.75 | G7: Absence de prééclampsie | H7: =C5 -> 352
B8: HTA gestationnelle | C8: =COUNTIF(Donnees!$U$2:$U$401,B8) -> 10 | D8: =C8/SUM($C$7:$C$11)*100 -> 2.5
B9: HTA chronique seule | C9: =COUNTIF(Donnees!$U$2:$U$401,B9) -> 15 | D9: =C9/SUM($C$7:$C$11)*100 -> 3.75
B10: Prééclampsie | C10: =COUNTIF(Donnees!$U$2:$U$401,B10) -> 40 | D10: =C10/SUM($C$7:$C$11)*100 -> 10
B11: Prééclampsie surajoutée | C11: =COUNTIF(Donnees!$U$2:$U$401,B11) -> 8 | D11: =C11/SUM($C$7:$C$11)*100 -> 2
A13: ="Prééclampsie : "&C6&" cas sur "&SUM(C5:C6)&" femmes, soit "&FIXED(D6,1)&" %" -> Prééclampsie : 48 cas sur 400 femmes, soit 12,0 %
A14: Attention : ce pourcentage décrit l'échantillon, pas la prévalence de la prééclampsie dans la population générale de Kara.

Sheet 4_Facteurs
A1: Partie C – Facteurs associés à la prééclampsie (Questions 5 à 9)
A2: Règle : effectifs attendus tous ≥ 5 → test du Chi-deux ; au moins un < 5 → test exact de Fisher. Seuil : 5 %.
A4: QUESTION 5 : Existe-t-il une association entre l'âge maternel et la prééclampsie ?
A5: H0 : la fréquence de la prééclampsie est la même dans toutes les tranches d'âge. H1 : elle diffère dans au moins une tranche.
B6: Prééclampsie | G6: Effectifs attendus sous H0
A7: Modalité | B7: Non | C7: Oui | D7: Total | E7: % sans prééclampsie | F7: % avec prééclampsie | G7: Non | H7: Oui
A8: Moins de 20 ans | B8: =COUNTIFS(Donnees!$W$2:$W$401,$A8,Donnees!$V$2:$V$401,B$7) -> 16 | C8: =COUNTIFS(Donnees!$W$2:$W$401,$A8,Donnees!$V$2:$V$401,C$7) -> 5 | D8: =B8+C8 -> 21 | E8: =B8/D8*100 -> 76.190476 | F8: =C8/D8*100 -> 23.809524 | G8: =$D8*B$12/$D$12 -> 18.48 | H8: =$D8*C$12/$D$12 -> 2.52
A9: 20-29 ans | B9: =COUNTIFS(Donnees!$W$2:$W$401,$A9,Donnees!$V$2:$V$401,B$7) -> 258 | C9: =COUNTIFS(Donnees!$W$2:$W$401,$A9,Donnees!$V$2:$V$401,C$7) -> 31 | D9: =B9+C9 -> 289 | E9: =B9/D9*100 -> 89.273356 | F9: =C9/D9*100 -> 10.726644 | G9: =$D9*B$12/$D$12 -> 254.32 | H9: =$D9*C$12/$D$12 -> 34.68
A10: 30-34 ans | B10: =COUNTIFS(Donnees!$W$2:$W$401,$A10,Donnees!$V$2:$V$401,B$7) -> 58 | C10: =COUNTIFS(Donnees!$W$2:$W$401,$A10,Donnees!$V$2:$V$401,C$7) -> 7 | D10: =B10+C10 -> 65 | E10: =B10/D10*100 -> 89.230769 | F10: =C10/D10*100 -> 10.769231 | G10: =$D10*B$12/$D$12 -> 57.2 | H10: =$D10*C$12/$D$12 -> 7.8
A11: 35 ans et plus | B11: =COUNTIFS(Donnees!$W$2:$W$401,$A11,Donnees!$V$2:$V$401,B$7) -> 20 | C11: =COUNTIFS(Donnees!$W$2:$W$401,$A11,Donnees!$V$2:$V$401,C$7) -> 5 | D11: =B11+C11 -> 25 | E11: =B11/D11*100 -> 80 | F11: =C11/D11*100 -> 20 | G11: =$D11*B$12/$D$12 -> 22 | H11: =$D11*C$12/$D$12 -> 3
A12: Total | B12: =SUM(B8:B11) -> 352 | C12: =SUM(C8:C11) -> 48 | D12: =SUM(D8:D11) -> 400 | F12: =C12/D12*100 -> 12
A14: Effectif attendu minimum | B14: =MIN(G8:H11) -> 2.52
A15: Test retenu | B15: =IF(B14>=5,"Chi-deux","Fisher") -> Fisher
A16: p-value du Chi-deux (Pearson) | B16: =IFERROR(CHITEST(B8:C11,G8:H11),"n/a") -> 0.18502327
A17: p-value du test exact de Fisher | B17: =Fisher_Q5!E10 -> 0.1648947
A18: p-value retenue | B18: =IFERROR(IF(B15="Chi-deux",B16,B17),"n/a") -> 0.1648947
A19: p-value affichée | B19: =IF(ISNUMBER(B18),IF(B18<0.001,"<0,001",FIXED(B18,3)),"n/a") -> 0,165
A20: Conclusion | B20: =IF(ISNUMBER(B18),IF(B18<0.05,"Association statistiquement significative (p < 0,05).","Association non démontrée ici (p >= 0,05). Cela ne prouve pas l'absence d'association."),"n/a") -> Association non démontrée ici (p >= 0,05). Cela ne prouve pas l'absence d'association.
A22: QUESTION 6 : Les femmes ayant un antécédent de prééclampsie présentent-elles plus souvent une prééclampsie ? (femmes déjà accouchées, antécédent renseigné)
A23: H0 : la fréquence de la prééclampsie est la même avec ou sans antécédent. H1 : elle diffère. (Analyse restreinte : parité ≥ 1 et antécédent Oui/Non)
B24: Prééclampsie | G24: Effectifs attendus sous H0
A25: Modalité | B25: Non | C25: Oui | D25: Total | E25: % sans prééclampsie | F25: % avec prééclampsie | G25: Non | H25: Oui
